Workbook

Sheet Старт
B2: ФИНАНСОВАЯ МОДЕЛЬ VERTOV — С ЧЕГО НАЧАТЬ
B3: Правило одно: СИНИЕ ячейки — меняешь ты, все остальные считаются сами. После любого изменения смотри проверку внизу P&L.
B5: КАК ПОЛЬЗОВАТЬСЯ — 4 ШАГА
B6: ШАГ 1 · Задай цели прибыли | C6: Блок «ЦЕЛИ ПРИБЫЛИ» вверху «Технического». Три группы клиентов (тратят 50% / 75% / 100% лимита): укажи долю каждой группы и какую чистую маржу хочешь с неё. Модель выведет среднюю цель и минимальную гарантированную маржу тарифов.
B7: ШАГ 2 · Задай размер тарифов | C7: Строка «КРЕДИТОВ В ТАРИФЕ»: сколько кредитов входит в Start / Pro / Studio / Elite. Цены посчитаются сами из целей прибыли и округлятся до …99. «Поправка маржи» — дорогие тарифы дают дешевле кредит.
B8: ШАГ 3 · Заполни каталог моделей | C8: Матрица «Модели из прода»: 22 реальные модели с ценами. Меняй кредиты за единицу и длину клипа; впиши токены Syntx (колонка Q) — сравнение посчитается.
B9: ШАГ 4 · Проверь прибыль | C9: P&L: полный отчёт о прибыли за месяц. Внизу — блок «Проверка»: чистая маржа, если клиенты тратят 50% / 75% / весь лимит, и сходимость с твоей целью.
B11: КАРТА ЛИСТОВ
B12: Экзекьютив | C12: Сводка на одну страницу: тарифы, экономика одной генерации, P&L, текущие настройки. Показывать инвестору.
B13: Тарифы | C13: Тарифы — утвержденные цены, кредиты, CM2 и единая матрица Vertov / Syntx / Higgsfield.
B14: Юнит-экономика | C14: Экономика одной генерации в 3 шага: во сколько обходится нам → сколько зарабатываем → то же на объёме за месяц.
B15: P&L | C15: Прибыль за месяц: выручка (подписки + докупки) → себестоимость → комиссии → постоянные расходы → маркетинг → налог → чистая прибыль. Внизу — проверка по сценариям.
B16: Технический | C16: Аудит цен — вендор, источник и confidence; обновлять перед инвест-пакетом.
B18: ЧАСТЫЕ ДЕЙСТВИЯ — ГДЕ МЕНЯТЬ
B19: Хочу другую маржу / другие цены | C19: Цели прибыли (доли групп и целевые маржи) — цены пересчитаются.
B20: Хочу дать больше/меньше генераций | C20: Размер тарифа в генерациях Seedance 2.0.
B21: Сменить банк перевода (A7 ↔ ВТБ) | C21: Переключатель коридора: 1 = A7 (0,37%), 2 = ВТБ (8,2%).
B22: Изменить долю резервного провайдера Nano | C22: Доля запросов через kie.ai — влияет на себестоимость картинок.
B23: Доля оплат СБП / карты | C23: Меняет комиссию эквайринга (СБП 0,7% vs карта 3,2%).
B24: УСН 6% ↔ 15% | C24: Переключатель налогового режима.
B25: Хостинг: грант / self-host / managed | C25: Сценарий постоянных расходов на инфраструктуру.
B26: Число клиентов, отток, стоимость привлечения | C26: Блок «Портфель и поведение».
B27: Цены докупки кредитов | C27: Блок «Top-up»: номиналы и ₽/кредит.
B29: Термины, если что-то непонятно — «Технический», блок «Справка» в самом низу.

Sheet Экзекьютив
B2: VERTOV — ЭКЗЕКЬЮТИВ-СВОДКА
B3: Утвержденная pricing-модель запуска: тарифы, CM2, Net margin P&L, себестоимость SKU и сравнение Vertov · Syntx · Higgsfield.
B5: 1. ТАРИФНАЯ СЕТКА (цена из пола маржи)
B6: Тариф | C6: Цена ₽/мес | D6: Видео veo-fast, ген/мес | E6: Картинки g3-pro, ген/мес | F6: ₽ за генерацию | G6: Мин. маржа
B7: Start | C7: =Тарифы!C7 -> 599 | D7: =Тарифы!C11 -> 5.5164319 | E7: =Тарифы!C15 -> 37.903226 | F7: =Тарифы!C17 -> 108.58468 | G7: =Тарифы!C8 -> 0.32307421
B8: Pro | C8: =Тарифы!D7 -> 1649 | D8: =Тарифы!D11 -> 20.657277 | E8: =Тарифы!D15 -> 141.93548 | F8: =Тарифы!D17 -> 79.826591 | G8: =Тарифы!D8 -> 0.11316117
B9: Studio | C9: =Тарифы!E7 -> 3799 | D9: =Тарифы!E11 -> 48.356808 | E9: =Тарифы!E15 -> 332.25806 | F9: =Тарифы!E17 -> 78.561845 | G9: =Тарифы!E8 -> 0.10040149
B10: Elite | C10: =Тарифы!F7 -> 5799 | D10: =Тарифы!F11 -> 74.647887 | E10: =Тарифы!F15 -> 512.90323 | F10: =Тарифы!F17 -> 77.684717 | G10: =Тарифы!F8 -> 0.091308413
B11: Ultra | C11: =Тарифы!G7 -> 11699 | D11: =Тарифы!G11 -> 152.58216 | E11: =Тарифы!G15 -> 1048.3871 | F11: =Тарифы!G17 -> 76.673446 | G11: =Тарифы!G8 -> 0.08056648
B12: 2. ЭКОНОМИКА ОДНОЙ ГЕНЕРАЦИИ
B13: Себестоимость 1 ген. veo-3-1 (8с), ₽ | C13: ='Юнит-экономика'!I18 -> 125.79871
B14: Себестоимость 1 ген. gemini-3-pro-image, ₽ | C14: ='Юнит-экономика'!I13 -> 9.0575072
B15: Продаём 1 видео-ген. (veo-fast) за, ₽ | C15: =TEXT(Тарифы!C17,"0")&"–"&TEXT(Тарифы!F17,"0")&" ₽" -> 109–78 ₽
B16: Прибыль с 1 видео-ген. на Elite (после комиссий и УСН) | C16: ='Юнит-экономика'!H20 -> 2.2991803
B18: 3. P&L ПРИ 1000 КЛИЕНТАХ
B19: Выручка (подписки + top-up) | C19: ='P&L'!C8 -> 2352000
B20: Валовая прибыль | C20: ='P&L'!C16 -> 1443226.6
B21: Чистая прибыль | C21: ='P&L'!C32 -> 924550.65
B22: Чистая маржа | C22: ='P&L'!C35 -> 0.39309126
B23: Worst Net margin при 100% расходовании | C23: ='P&L'!E44 -> 0.0029000331
B25: 4. КОНФИГУРАЦИЯ (текущие переключатели)
B26: Коридор | C26: =IF(Технический!C20=1,"A7 · 0,37%","ВТБ · 8,22%") -> A7 · 0,37%
B27: УСН | C27: =IF(Технический!C64=1,"Доходы 6% (взносы в зачёт)","Д−Р 15%") -> Доходы 6% (взносы в зачёт)
B28: Хостинг | C28: =CHOOSE(Технический!C73,"Грант (0 ₽)","Self-host 18k","Managed 52k") -> Managed 52k
B29: Доля оплат через СБП / доля резервного провайдера Nano | C29: =TEXT(Технический!C53,"0%")&" / "&TEXT(Технический!C38,"0%") -> 55% / 10%
B30: Курс ЦБ / использование | C30: =TEXT(Технический!C17,"0.0")&" ₽/$ / "&TEXT(Технический!C87,"0%") -> 85.0 ₽/$ / 66%
B32: 5. ГЕНЕРАЦИЙ КАЖДОЙ МОДЕЛИ В ТАРИФЕ (из матрицы)
B33: Модель | C33: Start | D33: Pro | E33: Studio | F33: Elite | G33: Ultra
B34: =Тарифы!$B$54 -> nano-banana | C34: =Тарифы!$M$54 -> 146.875 | D34: =Тарифы!$N$54 -> 550 | E34: =Тарифы!$O$54 -> 1287.5 | F34: =Тарифы!$P$54 -> 1987.5 | G34: =Тарифы!$Q$54 -> 4062.5
B35: =Тарифы!$B$55 -> recraft-v4 | C35: =Тарифы!$M$55 -> 47 | D35: =Тарифы!$N$55 -> 176 | E35: =Тарифы!$O$55 -> 412 | F35: =Тарифы!$P$55 -> 636 | G35: =Тарифы!$Q$55 -> 1300
B36: =Тарифы!$B$56 -> gpt-image-2 | C36: =Тарифы!$M$56 -> 117.5 | D36: =Тарифы!$N$56 -> 440 | E36: =Тарифы!$O$56 -> 1030 | F36: =Тарифы!$P$56 -> 1590 | G36: =Тарифы!$Q$56 -> 3250
B37: =Тарифы!$B$57 -> recraft-v4-vector | C37: =Тарифы!$M$57 -> 29.375 | D37: =Тарифы!$N$57 -> 110 | E37: =Тарифы!$O$57 -> 257.5 | F37: =Тарифы!$P$57 -> 397.5 | G37: =Тарифы!$Q$57 -> 812.5
B38: =Тарифы!$B$58 -> nano-banana-2-lite | C38: =Тарифы!$M$58 -> 146.875 | D38: =Тарифы!$N$58 -> 550 | E38: =Тарифы!$O$58 -> 1287.5 | F38: =Тарифы!$P$58 -> 1987.5 | G38: =Тарифы!$Q$58 -> 4062.5
B39: =Тарифы!$B$59 -> nano-banana-2 | C39: =Тарифы!$M$59 -> 69.117647 | D39: =Тарифы!$N$59 -> 258.82353 | E39: =Тарифы!$O$59 -> 605.88235 | F39: =Тарифы!$P$59 -> 935.29412 | G39: =Тарифы!$Q$59 -> 1911.7647
B40: =Тарифы!$B$60 -> nano-banana-pro | C40: =Тарифы!$M$60 -> 37.903226 | D40: =Тарифы!$N$60 -> 141.93548 | E40: =Тарифы!$O$60 -> 332.25806 | F40: =Тарифы!$P$60 -> 512.90323 | G40: =Тарифы!$Q$60 -> 1048.3871
B41: =Тарифы!$B$61 -> flux-2-pro · 2MP | C41: =Тарифы!$M$61 -> 23.5 | D41: =Тарифы!$N$61 -> 88 | E41: =Тарифы!$O$61 -> 206 | F41: =Тарифы!$P$61 -> 318 | G41: =Тарифы!$Q$61 -> 650
B42: =Тарифы!$B$62 -> seedream-4-5 · до 4K | C42: =Тарифы!$M$62 -> 78.333333 | D42: =Тарифы!$N$62 -> 293.33333 | E42: =Тарифы!$O$62 -> 686.66667 | F42: =Тарифы!$P$62 -> 1060 | G42: =Тарифы!$Q$62 -> 2166.6667
B43: =Тарифы!$B$64 -> happyhorse-1-0 | C43: =Тарифы!$M$64 -> 5.0646552 | D43: =Тарифы!$N$64 -> 18.965517 | E43: =Тарифы!$O$64 -> 44.396552 | F43: =Тарифы!$P$64 -> 68.534483 | G43: =Тарифы!$Q$64 -> 140.08621
B44: =Тарифы!$B$65 -> happyhorse-1-1 | C44: =Тарифы!$M$65 -> 5.0646552 | D44: =Тарифы!$N$65 -> 18.965517 | E44: =Тарифы!$O$65 -> 44.396552 | F44: =Тарифы!$P$65 -> 68.534483 | G44: =Тарифы!$Q$65 -> 140.08621
B45: =Тарифы!$B$66 -> veo-3-1 Quality · 720p | C45: =Тарифы!$M$66 -> 0 | D45: =Тарифы!$N$66 -> 0 | E45: =Тарифы!$O$66 -> 0 | F45: =Тарифы!$P$66 -> 0 | G45: =Тарифы!$Q$66 -> 0
...

Sheet Сводная
B2: СВОДНАЯ — ЦЕНЫ ($ и ₽) И ГЕНЕРАЦИИ ПО МОДЕЛЯМ: МЫ · SYNTX · HIGGSFIELD
B3: ₽-цена конкурентов = $ × курс × (1+5% потерь ВТБ при оплате из РФ). Наша $-цена — справочно (₽ ÷ курс).
B5: VERTOV
B6: Цена, $/мес → | C6: =Тарифы!C7/Технический!$C$17 -> 7.0470588 | D6: =Тарифы!D7/Технический!$C$17 -> 19.4 | E6: =Тарифы!E7/Технический!$C$17 -> 44.694118 | F6: =Тарифы!F7/Технический!$C$17 -> 68.223529 | G6: =Тарифы!G7/Технический!$C$17 -> 137.63529
B7: Цена, ₽/мес (для РФ) → | C7: =Тарифы!C7 -> 599 | D7: =Тарифы!D7 -> 1649 | E7: =Тарифы!E7 -> 3799 | F7: =Тарифы!F7 -> 5799 | G7: =Тарифы!G7 -> 11699
B8: Модель | C8: Start | D8: Pro | E8: Studio | F8: Elite | G8: Ultra
B9: =Тарифы!$B$54 -> nano-banana | C9: =Тарифы!$M$54 -> 146.875 | D9: =Тарифы!$N$54 -> 550 | E9: =Тарифы!$O$54 -> 1287.5 | F9: =Тарифы!$P$54 -> 1987.5 | G9: =Тарифы!$Q$54 -> 4062.5
B10: =Тарифы!$B$55 -> recraft-v4 | C10: =Тарифы!$M$55 -> 47 | D10: =Тарифы!$N$55 -> 176 | E10: =Тарифы!$O$55 -> 412 | F10: =Тарифы!$P$55 -> 636 | G10: =Тарифы!$Q$55 -> 1300
B11: =Тарифы!$B$56 -> gpt-image-2 | C11: =Тарифы!$M$56 -> 117.5 | D11: =Тарифы!$N$56 -> 440 | E11: =Тарифы!$O$56 -> 1030 | F11: =Тарифы!$P$56 -> 1590 | G11: =Тарифы!$Q$56 -> 3250
B12: =Тарифы!$B$57 -> recraft-v4-vector | C12: =Тарифы!$M$57 -> 29.375 | D12: =Тарифы!$N$57 -> 110 | E12: =Тарифы!$O$57 -> 257.5 | F12: =Тарифы!$P$57 -> 397.5 | G12: =Тарифы!$Q$57 -> 812.5
B13: =Тарифы!$B$58 -> nano-banana-2-lite | C13: =Тарифы!$M$58 -> 146.875 | D13: =Тарифы!$N$58 -> 550 | E13: =Тарифы!$O$58 -> 1287.5 | F13: =Тарифы!$P$58 -> 1987.5 | G13: =Тарифы!$Q$58 -> 4062.5
B14: =Тарифы!$B$59 -> nano-banana-2 | C14: =Тарифы!$M$59 -> 69.117647 | D14: =Тарифы!$N$59 -> 258.82353 | E14: =Тарифы!$O$59 -> 605.88235 | F14: =Тарифы!$P$59 -> 935.29412 | G14: =Тарифы!$Q$59 -> 1911.7647
B15: =Тарифы!$B$60 -> nano-banana-pro | C15: =Тарифы!$M$60 -> 37.903226 | D15: =Тарифы!$N$60 -> 141.93548 | E15: =Тарифы!$O$60 -> 332.25806 | F15: =Тарифы!$P$60 -> 512.90323 | G15: =Тарифы!$Q$60 -> 1048.3871
B16: =Тарифы!$B$61 -> flux-2-pro · 2MP | C16: =Тарифы!$M$61 -> 23.5 | D16: =Тарифы!$N$61 -> 88 | E16: =Тарифы!$O$61 -> 206 | F16: =Тарифы!$P$61 -> 318 | G16: =Тарифы!$Q$61 -> 650
B17: =Тарифы!$B$62 -> seedream-4-5 · до 4K | C17: =Тарифы!$M$62 -> 78.333333 | D17: =Тарифы!$N$62 -> 293.33333 | E17: =Тарифы!$O$62 -> 686.66667 | F17: =Тарифы!$P$62 -> 1060 | G17: =Тарифы!$Q$62 -> 2166.6667
B18: =Тарифы!$B$64 -> happyhorse-1-0 | C18: =Тарифы!$M$64 -> 5.0646552 | D18: =Тарифы!$N$64 -> 18.965517 | E18: =Тарифы!$O$64 -> 44.396552 | F18: =Тарифы!$P$64 -> 68.534483 | G18: =Тарифы!$Q$64 -> 140.08621
B19: =Тарифы!$B$65 -> happyhorse-1-1 | C19: =Тарифы!$M$65 -> 5.0646552 | D19: =Тарифы!$N$65 -> 18.965517 | E19: =Тарифы!$O$65 -> 44.396552 | F19: =Тарифы!$P$65 -> 68.534483 | G19: =Тарифы!$Q$65 -> 140.08621
B20: =Тарифы!$B$66 -> veo-3-1 Quality · 720p | C20: =Тарифы!$M$66 -> 0 | D20: =Тарифы!$N$66 -> 0 | E20: =Тарифы!$O$66 -> 0 | F20: =Тарифы!$P$66 -> 0 | G20: =Тарифы!$Q$66 -> 0
B21: =Тарифы!$B$67 -> veo-3-1-fast · 720p | C21: =Тарифы!$M$67 -> 0 | D21: =Тарифы!$N$67 -> 0 | E21: =Тарифы!$O$67 -> 0 | F21: =Тарифы!$P$67 -> 0 | G21: =Тарифы!$Q$67 -> 0
B22: =Тарифы!$B$68 -> veo-3-1-lite · 720p | C22: =Тарифы!$M$68 -> 0 | D22: =Тарифы!$N$68 -> 0 | E22: =Тарифы!$O$68 -> 0 | F22: =Тарифы!$P$68 -> 0 | G22: =Тарифы!$Q$68 -> 0
B24: =Тарифы!$B$70 -> grok-imagine · 720p · Kie | C24: =Тарифы!$M$70 -> 26.111111 | D24: =Тарифы!$N$70 -> 97.777778 | E24: =Тарифы!$O$70 -> 228.88889 | F24: =Тарифы!$P$70 -> 353.33333 | G24: =Тарифы!$Q$70 -> 722.22222
B25: =Тарифы!$B$71 -> gemini-omni-flash · 720p | C25: =Тарифы!$M$71 -> 4.1666667 | D25: =Тарифы!$N$71 -> 15.602837 | E25: =Тарифы!$O$71 -> 36.524823 | F25: =Тарифы!$P$71 -> 56.382979 | G25: =Тарифы!$Q$71 -> 115.24823
B26: =Тарифы!$B$72 -> seedance-2-0 · 1080p · OpenRouter | C26: =Тарифы!$M$72 -> 1.8302181 | D26: =Тарифы!$N$72 -> 6.8535826 | E26: =Тарифы!$O$72 -> 16.043614 | F26: =Тарифы!$P$72 -> 24.766355 | G26: =Тарифы!$Q$72 -> 50.623053
B27: =Тарифы!$B$73 -> seedance-2-0-fast · 720p | C27: =Тарифы!$M$73 -> 5.6490385 | D27: =Тарифы!$N$73 -> 21.153846 | E27: =Тарифы!$O$73 -> 49.519231 | F27: =Тарифы!$P$73 -> 76.442308 | G27: =Тарифы!$Q$73 -> 156.25
B28: =Тарифы!$B$74 -> wan-2-7 · 720p (kie) | C28: =Тарифы!$M$74 -> 0 | D28: =Тарифы!$N$74 -> 0 | E28: =Тарифы!$O$74 -> 0 | F28: =Тарифы!$P$74 -> 0 | G28: =Тарифы!$Q$74 -> 0
B29: =Тарифы!$B$75 -> kling-v3-standard | C29: =Тарифы!$M$75 -> 3.3571429 | D29: =Тарифы!$N$75 -> 12.571429 | E29: =Тарифы!$O$75 -> 29.428571 | F29: =Тарифы!$P$75 -> 45.428571 | G29: =Тарифы!$Q$75 -> 92.857143
B30: =Тарифы!$B$91 -> seedream-5-0-pro · 1K | C30: =Тарифы!$M$91 -> 78.333333 | D30: =Тарифы!$N$91 -> 293.33333 | E30: =Тарифы!$O$91 -> 686.66667 | F30: =Тарифы!$P$91 -> 1060 | G30: =Тарифы!$Q$91 -> 2166.6667
B31: =Тарифы!$B$92 -> seedream-5-0-lite | C31: =Тарифы!$M$92 -> 117.5 | D31: =Тарифы!$N$92 -> 440 | E31: =Тарифы!$O$92 -> 1030 | F31: =Тарифы!$P$92 -> 1590 | G31: =Тарифы!$Q$92 -> 3250
B33: SYNTX (прямой конкурент)
B34: Цена, $/мес → | C34: =Технический!C107/Технический!$C$17 -> 10.470588 | D34: =Технический!D107/Технический!$C$17 -> 19.882353 | E34: =Технический!E107/Технический!$C$17 -> 46.941176 | F34: =Технический!F107/Технический!$C$17 -> 70.470588 | G34: =Технический!G107/Технический!$C$17 -> 141.05882
B35: Цена, ₽/мес (для РФ) → | C35: =Технический!C107 -> 890 | D35: =Технический!D107 -> 1690 | E35: =Технический!E107 -> 3990 | F35: =Технический!F107 -> 5990 | G35: =Технический!G107 -> 11990
B36: Модель | C36: Basic | D36: Pro | E36: VIP | F36: Elite | G36: Ultra El.
B37: =Тарифы!$B$54 -> nano-banana | C37: =Тарифы!$S$54 -> 173.33333 | D37: =Тарифы!$T$54 -> 457 | E37: =Тарифы!$U$54 -> 1133.3333 | F37: =Тарифы!$V$54 -> 1733.3333 | G37: =Тарифы!$W$54 -> 2000
B38: =Тарифы!$B$55 -> recraft-v4 | C38: =Тарифы!$S$55 | D38: =Тарифы!$T$55 | E38: =Тарифы!$U$55 | F38: =Тарифы!$V$55 | G38: =Тарифы!$W$55
B39: =Тарифы!$B$56 -> gpt-image-2 | C39: =Тарифы!$S$56 -> 130 | D39: =Тарифы!$T$56 -> 342.75 | E39: =Тарифы!$U$56 -> 850 | F39: =Тарифы!$V$56 -> 1300 | G39: =Тарифы!$W$56 -> 1500
B40: =Тарифы!$B$57 -> recraft-v4-vector | C40: =Тарифы!$S$57 | D40: =Тарифы!$T$57 | E40: =Тарифы!$U$57 | F40: =Тарифы!$V$57 | G40: =Тарифы!$W$57
B41: =Тарифы!$B$58 -> nano-banana-2-lite | C41: =Тарифы!$S$58 -> 200 | D41: =Тарифы!$T$58 -> 527.30769 | E41: =Тарифы!$U$58 -> 1307.6923 | F41: =Тарифы!$V$58 -> 2000 | G41: =Тарифы!$W$58 -> 2307.6923
B42: =Тарифы!$B$59 -> nano-banana-2 | C42: =Тарифы!$S$59 -> 86.666667 | D42: =Тарифы!$T$59 -> 228.5 | E42: =Тарифы!$U$59 -> 566.66667 | F42: =Тарифы!$V$59 -> 866.66667 | G42: =Тарифы!$W$59 -> 1000
B43: =Тарифы!$B$60 -> nano-banana-pro | C43: =Тарифы!$S$60 -> 130 | D43: =Тарифы!$T$60 -> 342.75 | E43: =Тарифы!$U$60 -> 850 | F43: =Тарифы!$V$60 -> 1300 | G43: =Тарифы!$W$60 -> 1500
B44: =Тарифы!$B$61 -> flux-2-pro · 2MP | C44: =Тарифы!$S$61 | D44: =Тарифы!$T$61 | E44: =Тарифы!$U$61 | F44: =Тарифы!$V$61 | G44: =Тарифы!$W$61
...

Sheet Сетка FX
A1: ГЛАВНЫЙ ЛИСТ. Цены — колонка O «КРЕДИТОВ/КЛИП». Курс 85, кредит 0,331 ₽. ВНИМАНИЕ: колонка I — бенчмарк, на котором построены цены, — содержит ошибку: одно значение продублировано на все разрешения модели. Проверенные значения в колонке T, ФАКТИЧЕСКОЕ сравнение с Syntx в колонке V. Цены заморожены сознательно — решение о снижении отложено. Колонки W–Y показывают цену, сравнение и маржу, если снижение принять.
A2: Правило: кредитов = максимум из трёх (потолок щедрости +28% к Syntx / маржа 25% / безубыток при уходе на резерв). Маржа — ВАЛОВАЯ, только вендорская себестоимость. Fallback legs signed 2026-08-14: gemini-2.5 flash image Kie $0.02 t2i/edit; GPT Image 2 Kie $0.03/$0.05/$0.08 by low/medium/high and t2i/i2i. GPT quality reserves are costed for margin governance but remain unarmed until Kie quality mapping is approved; sell prices unchanged.
A3: КУРС USD/RUB → | B3: 85 | C3: ЕДИНЫЙ КУРС КНИГИ. Синхронизирован с «Технический» C17 и «Аудит цен». Обновлён 03.08.2026. | E3: Landed ₽/$ OpenRouter | F3: =$B$3*1.2492 -> 106.182
A4: Цена кредита, ₽ | B4: 0.331111 | C4: самый дешёвый продаваемый кредит | E4: Landed ₽/$ direct (kie/lao) | F4: =$B$3*1.1839 -> 100.6315
A5: Целевая валовая маржа | B5: 0.25 | C5: на основном поставщике
A6: Маржа в худшей длительности | B6: 0.15 | C6: для veo: маржа на 4-сек клипе при базовом курсе. 15% здесь = 0% при курсе 100 (не в убыток).
AJ7: ЛЕСТНИЦА НОГ ОТКРЫТА НА ТРЕТЬЮ ПОЗИЦИЮ 11.08.2026. Формат готов, НИ ОДНА ставка не подписана: все цифры новых вендоров — опубликованные карточки без инвойса. Правило T4 в силе: неоплаченная ставка не маршрутизируется. | AM7: БАЗА ТАРИФИКАЦИИ ПЕРЕЕХАЛА СО СТРОКИ НА НОГУ 11.08.2026. Раньше строка хранила одну базу на всю лестницу — это и есть дыра, о которой пишет dev: вендор с плоской ценой за клип и вендор с ценой за секунду не могут стоять на одной строке под одной базой. Пусто = нога тарифицируется так же, как строка. | AO7: ПЛОЩАДЬ ВЫДАЧИ В МЕГАПИКСЕЛЯХ — для ног, которые тарифицируются за мегапиксель. Ярлык ступени не является драйвером затрат: у kie «2K» это 1536x1536 = 2,36 МП, а 2048x2048 = 4,19 МП, разница в 1,8 раза при одинаковом названии. Аспект сюда же: 16:9 и 1:1 на «одной ступени» — разная площадь. | AP7: ПОДКЛЮЧЁННОСТЬ МАРШРУТА — ТРЕТЬЯ ОСЬ, ЗАВЕДЕНА 11.08.2026. Ставка отвечает «сколько стоит», выбор вендора — «к кому идём», и ни одна из двух не отвечает «а можем ли мы его позвать». Правило T4 дополняется: неоплаченная ставка не маршрутизируется, И неподключённый маршрут не продаётся. Пусто = не подтверждено; строка с неподключённой первой ногой в экспорт не выгружается.
A8: Модель | B8: Тарификация | C8: Сек в клипе | D8: Мин. сек | E8: Канал | F8: $ за ед. | G8: Резерв канал | H8: $ резерв | I8: I · Syntx ток. — ПРОВЕРЕНО 28.07, задаёт потолок щедрости | J8: J · ЦЕНА НА САЙТЕ сегодня | K8: Себест ₽/клип | L8: Потолок +28% | M8: По марже | N8: Безубыток резерв | O8: O · ЦЕНА ПО ПРАВИЛУ сетки | P8: Кредитов/сек | Q8: Маржа | R8: R · УСТАРЕЛО — считается от ошибочного I. НЕ ЧИТАТЬ | T8: T · Syntx токены — ПРОВЕРЕНО | U8: Источник / статус | V8: V · vs Syntx ФАКТ (при ценах O) | W8: Цена по проверенному потолку | X8: vs Syntx при этой цене | Y8: Маржа при этой цене | Z8: Z · ступень качества +15% | AA8: СПИСЫВАТЬ — кредитов | AB8: за сколько секунд | AC8: кредитов за секунду | AD8: Посредник — основная нога | AE8: Посредник — резервная нога | AF8: SKU у поставщика | AG8: Достоверность | AH8: ПОРОГ МАРЖИ строки | AI8: AI · РИСК МАРШРУТА | AJ8: AJ · Посредник — 3-я нога | AK8: AK · Канал 3-й ноги | AL8: AL · $ за ед., 3-я нога | AM8: AM · База тариф. — нога 2 | AN8: AN · База тариф. — нога 3 | AO8: AO · Площадь выдачи, МП | AP8: AP · Маршрут ноги 1 подключён | AQ8: AQ · Маршрут ноги 2 подключён | AR8: AR · Маршрут ноги 3 подключён
A9: Veo Quality 720p | B9: за клип | C9: 8 | D9: 8 | E9: direct | F9: 1.25 | G9: — | H9: — | I9: 119 | J9: 850 | K9: =F9*1*IF(E9="OpenRouter",$F$3,$F$4) -> 125.78938 | L9: =ROUNDUP(5.014*I9,0) -> 597 | M9: =ROUNDUP(K9*(C9/D9)/($B$4*(1-AH9)),0) -> 507 | N9: 0 | O9: =MAX(L9,M9,N9) -> 597 | P9: =ROUND(O9/C9,0) -> 75 | Q9: =1-K9/(O9*$B$4) -> 0.36365004 | T9: 119 | U9: публичный прайс Syntx, подтверждён владельцем 03.08.2026 | V9: =(4400/O9)/(685.5/T9)-1 -> 0.27943388 | W9: =MAX(ROUNDUP(5.014*T9,0),M9,N9) -> 597 | X9: =(4400/W9)/(685.5/T9)-1 -> 0.27943388 | Y9: =1-K9/(W9*$B$4) -> 0.36365004 | AA9: =O9 -> 597 | AB9: =C9 -> 8 | AC9: =IF(B9="шт","—",P9) -> 75 | AD9: Kie | AE9: — | AF9: veo-3-1 | AG9: HIGH — бенчмарк Syntx подтверждён владельцем 03.08.2026 | AH9: 0.25 | AP9: да
A10: Veo Quality 1080p | B10: за клип | C10: 8 | D10: 8 | E10: direct | F10: 1.275 | G10: — | H10: — | I10: 119 | J10: 867 | K10: =F10*1*IF(E10="OpenRouter",$F$3,$F$4) -> 128.30516 | L10: =ROUNDUP(5.014*I10,0) -> 597 | M10: =ROUNDUP(K10*(C10/D10)/($B$4*(1-AH10)),0) -> 517 | N10: 0 | O10: =MAX(L10,M10,N10) -> 597 | P10: =ROUND(O10/C10,0) -> 75 | Q10: =1-K10/(O10*$B$4) -> 0.35092304 | T10: 119 | U10: публичный прайс Syntx, подтверждён владельцем 03.08.2026 | V10: =(4400/O10)/(685.5/T10)-1 -> 0.27943388 | W10: =MAX(ROUNDUP(5.014*T10,0),M10,N10) -> 597 | X10: =(4400/W10)/(685.5/T10)-1 -> 0.27943388 | Y10: =1-K10/(W10*$B$4) -> 0.35092304 | AA10: =O10 -> 597 | AB10: =C10 -> 8 | AC10: =IF(B10="шт","—",P10) -> 75 | AD10: Kie | AE10: — | AF10: veo-3-1 | AG10: HIGH — бенчмарк Syntx подтверждён владельцем 03.08.2026 | AH10: 0.25 | AP10: да
A11: Veo Fast 720p | B11: за клип | C11: 8 | D11: 8 | E11: direct | F11: 0.3 | G11: — | H11: — | I11: 19 | J11: 213 | K11: =F11*1*IF(E11="OpenRouter",$F$3,$F$4) -> 30.18945 | L11: =ROUNDUP(5.014*I11,0) -> 96 | M11: =ROUNDUP(K11*(C11/D11)/($B$4*(1-AH11)),0) -> 122 | N11: 0 | O11: =MAX(L11,M11,N11) -> 122 | P11: =ROUND(O11/C11,0) -> 15 | Q11: =1-K11/(O11*$B$4) -> 0.25265392 | T11: 19 | U11: публичный прайс Syntx, подтверждён владельцем 03.08.2026 | V11: =(4400/O11)/(685.5/T11)-1 -> -0.00037067595 | W11: =MAX(ROUNDUP(5.014*T11,0),M11,N11) -> 122 | X11: =(4400/W11)/(685.5/T11)-1 -> -0.00037067595 | Y11: =1-K11/(W11*$B$4) -> 0.25265392 | AA11: =O11 -> 122 | AB11: =C11 -> 8 | AC11: =IF(B11="шт","—",P11) -> 15 | AD11: Kie | AE11: — | AF11: veo-3-1 | AG11: HIGH — бенчмарк Syntx подтверждён владельцем 03.08.2026 | AH11: 0.25 | AP11: да
A12: Veo Fast 1080p | B12: за клип | C12: 8 | D12: 8 | E12: direct | F12: 0.325 | G12: — | H12: — | I12: 19 | J12: 255 | K12: =F12*1*IF(E12="OpenRouter",$F$3,$F$4) -> 32.705238 | L12: =ROUNDUP(5.014*I12,0) -> 96 | M12: =ROUNDUP(K12*(C12/D12)/($B$4*(1-AH12)),0) -> 132 | N12: 0 | O12: =MAX(L12,M12,N12) -> 132 | P12: =ROUND(O12/C12,0) -> 17 | Q12: =1-K12/(O12*$B$4) -> 0.2517103 | T12: 19 | U12: публичный прайс Syntx, подтверждён владельцем 03.08.2026 | V12: =(4400/O12)/(685.5/T12)-1 -> -0.07610017 | W12: =MAX(ROUNDUP(5.014*T12,0),M12,N12) -> 132 | X12: =(4400/W12)/(685.5/T12)-1 -> -0.07610017 | Y12: =1-K12/(W12*$B$4) -> 0.2517103 | AA12: =O12 -> 132 | AB12: =C12 -> 8 | AC12: =IF(B12="шт","—",P12) -> 17 | AD12: Kie | AE12: — | AF12: veo-3-1 | AG12: HIGH — бенчмарк Syntx подтверждён владельцем 03.08.2026 | AH12: 0.25 | AP12: да
A13: Veo Lite 720p | B13: за клип | C13: 8 | D13: 8 | E13: direct | F13: 0.15 | G13: — | H13: — | I13: 13 | J13: 107 | K13: =F13*1*IF(E13="OpenRouter",$F$3,$F$4) -> 15.094725 | L13: =ROUNDUP(5.014*I13,0) -> 66 | M13: =ROUNDUP(K13*(C13/D13)/($B$4*(1-AH13)),0) -> 61 | N13: 0 | O13: =MAX(L13,M13,N13) -> 66 | P13: =ROUND(O13/C13,0) -> 8 | Q13: =1-K13/(O13*$B$4) -> 0.30927105 | T13: 13 | U13: публичный прайс Syntx, подтверждён владельцем 03.08.2026 | V13: =(4400/O13)/(685.5/T13)-1 -> 0.26428398 | W13: =MAX(ROUNDUP(5.014*T13,0),M13,N13) -> 66 | X13: =(4400/W13)/(685.5/T13)-1 -> 0.26428398 | Y13: =1-K13/(W13*$B$4) -> 0.30927105 | AA13: =O13 -> 66 | AB13: =C13 -> 8 | AC13: =IF(B13="шт","—",P13) -> 8 | AD13: Kie | AE13: — | AF13: veo-3-1 | AG13: HIGH — бенчмарк Syntx подтверждён владельцем 03.08.2026 | AH13: 0.25 | AP13: да
A14: Veo Lite 1080p | B14: за клип | C14: 8 | D14: 8 | E14: direct | F14: 0.175 | G14: — | H14: — | I14: 13 | J14: 170 | K14: =F14*1*IF(E14="OpenRouter",$F$3,$F$4) -> 17.610512 | L14: =ROUNDUP(5.014*I14,0) -> 66 | M14: =ROUNDUP(K14*(C14/D14)/($B$4*(1-AH14)),0) -> 71 | N14: 0 | O14: =MAX(L14,M14,N14) -> 71 | P14: =ROUND(O14/C14,0) -> 9 | Q14: =1-K14/(O14*$B$4) -> 0.25089959 | T14: 13 | U14: публичный прайс Syntx, подтверждён владельцем 03.08.2026 | V14: =(4400/O14)/(685.5/T14)-1 -> 0.17524989 | W14: =MAX(ROUNDUP(5.014*T14,0),M14,N14) -> 71 | X14: =(4400/W14)/(685.5/T14)-1 -> 0.17524989 | Y14: =1-K14/(W14*$B$4) -> 0.25089959 | AA14: =O14 -> 71 | AB14: =C14 -> 8 | AC14: =IF(B14="шт","—",P14) -> 9 | AD14: Kie | AE14: — | AF14: veo-3-1 | AG14: HIGH — бенчмарк Syntx подтверждён владельцем 03.08.2026 | AH14: 0.25 | AP14: да
A15: Seedance 2.0 4K | B15: сек | C15: 5 | D15: 5 | E15: direct | F15: 1.04 | G15: — | H15: — | I15: — | K15: =F15*C15*IF(E15="OpenRouter",$F$3,$F$4) -> 523.2838 | L15: 0 | M15: =ROUNDUP(K15*(C15/D15)/($B$4*(1-IF(B15="фикс",$B$6,AH15))),0) -> 2108 | N15: 0 | O15: =MAX(L15,M15,N15) -> 2108 | P15: =ROUND(O15/C15,0) -> 422 | Q15: =1-K15/(O15*$B$4) -> 0.2502904 | U15: ЦЕНА СНИЖЕНА 11.08.2026. Держал её член «безубыточность резерва»: цена выставлялась так, чтобы переключение на OpenRouter ($1,361/с) прошло в ноль. Но по R-11 от 27.07 Seedance 4K НИКОГДА не переключается — при 84,8 ₽ убытка на генерацию одна ступень съедала бы дневной лимит за шестьдесят роликов. То есть мы брали с клиента 75 кредитов за страховку, которой сами постановили не пользоваться. Цена теперь считается по единственной ноге, которая реально обслуживает: kie $1,040/с при 25%. ПРИНЦИП: мы берём деньги за страховку, которую готовы заявить, и не берём за ту, от которой отказались письменно. НОГА OPENROUTER СНЯТА, а не просто не оплачена: публиковать ногу, которой по R-11 запрещено пользоваться, значит разрешить движку ею воспользоваться. Строка обслуживается одним kie; при его недоступности 4K не отдаётся, клиенту предлагается 1080p — это и есть решение от 27.07, теперь выраженное данными, а не только текстом. | AA15: =O15 -> 2108 | AB15: =C15 -> 5 | AC15: =IF(B15="шт","—",P15) -> 422 | AD15: Kie | AE15: — | AF15: seedance-2-0 | AG15: HIGH — ставки платно подтверждены; имена посредников исправлены 10.08.2026 (были переставлены) | AH15: =$B$5 -> 0.25 | AP15: да
A16: Seedance 2.0 1080p | B16: сек | C16: 5 | D16: 5 | E16: OpenRouter | F16: 0.34 | G16: direct | H16: 0.51 | I16: 112.25 | J16: 642 | K16: =F16*C16*IF(E16="OpenRouter",$F$3,$F$4) -> 180.5094 | L16: =ROUNDUP(5.014*I16,0) -> 563 | M16: =ROUNDUP(K16*(C16/D16)/($B$4*(1-IF(B16="фикс",$B$6,AH16))),0) -> 727 | N16: =ROUNDUP(H16*C16*IF(G16="OpenRouter",$F$3,$F$4)/$B$4,0) -> 775 | O16: =MAX(L16,M16,N16) -> 775 | P16: =ROUND(O16/C16,0) -> 155 | Q16: =1-K16/(O16*$B$4) -> 0.29656413 | T16: 112.25 | U16: публичный прайс Syntx 28.07.2026, цена «итого», пересчёт на длину нашего клипа РЕШЕНИЕ ВЛАДЕЛЬЦА 11.08.2026 — НАДБАВКА ЗА РЕЗЕРВ ОСТАЁТСЯ. Правило цены остаётся из четырёх членов: MAX(потолок +28% vs Syntx; цена по марже 25%; БЕЗУБЫТОК РЕЗЕРВА; ступень качества +15%). Вопрос ставился и закрыт: четвёртый член перебивает цену на 8 строках из 91, и на этих строках клиент оплачивает вторую ногу. Владелец рассмотрел цену решения и принял её. ЧЕГО ЭТО СТОИТ, ЧТОБЫ НИКТО НЕ ПЕРЕСЧИТЫВАЛ ЗАНОВО: на Seedance 1080p 775 вместо 727 — это −7,0% против Syntx вместо −0,9%, то есть страховка стоит 6 п.п. конкурентоспособности. На Gemini Omni 273 вместо 257 — −34,2% вместо −30,1%. На остальных строках надбавка стоит 1-2 кредита и на сравнение с конкурентом не влияет. ЧТО ЭТО ПОКУПАЕТ: переключение на резерв бесплатно для нас в момент отказа — резерв на этих строках выходит ровно в ноль, а не в минус, поэтому R-1 выполняется без исключений и бюджет отказов по R-11 не расходуется. ИЗВЕСТНОЕ ПОБОЧНОЕ СЛЕДСТВИЕ: при этом правиле добавление ЛЮБОЙ новой ноги может цену только поднять, никогда не опустить. Третья нога, под которую 11.08 открыт формат, работает против клиента до тех пор, пока это правило действует. Пересматривать при подключении первого третьего вендора. | V16: =(4400/O16)/(685.5/T16)-1 -> -0.070327757 | W16: =MAX(ROUNDUP(5.014*T16,0),M16,N16) -> 775 | X16: =(4400/W16)/(685.5/T16)-1 -> -0.070327757 | Y16: =1-K16/(W16*$B$4) -> 0.29656413 | AA16: =O16 -> 775 | AB16: =C16 -> 5 | AC16: =IF(B16="шт","—",P16) -> 155 | AD16: OpenRouter | AE16: Kie | AF16: seedance-2-0 | AG16: HIGH | AH16: =$B$5 -> 0.25 | AP16: да | AQ16: да
A17: Seedance 2.0 720p | B17: сек | C17: 5 | D17: 5 | E17: OpenRouter | F17: 0.151 | G17: direct | H17: 0.205 | I17: 45.375 | J17: 282 | K17: =F17*C17*IF(E17="OpenRouter",$F$3,$F$4) -> 80.16741 | L17: =ROUNDUP(5.014*I17,0) -> 228 | M17: =ROUNDUP(K17*(C17/D17)/($B$4*(1-IF(B17="фикс",$B$6,AH17))),0) -> 323 | N17: =ROUNDUP(H17*C17*IF(G17="OpenRouter",$F$3,$F$4)/$B$4,0) -> 312 | O17: =MAX(L17,M17,N17) -> 323 | P17: =ROUND(O17/C17,0) -> 65 | Q17: =1-K17/(O17*$B$4) -> 0.25041356 | T17: 45.375 | U17: публичный прайс Syntx 28.07.2026, цена «итого», пересчёт на длину нашего клипа | V17: =(4400/O17)/(685.5/T17)-1 -> -0.098305682 | W17: =MAX(ROUNDUP(5.014*T17,0),M17,N17) -> 323 | X17: =(4400/W17)/(685.5/T17)-1 -> -0.098305682 | Y17: =1-K17/(W17*$B$4) -> 0.25041356 | AA17: =O17 -> 323 | AB17: =C17 -> 5 | AC17: =IF(B17="шт","—",P17) -> 65 | AD17: OpenRouter | AE17: Kie | AF17: seedance-2-0 | AG17: HIGH | AH17: =$B$5 -> 0.25 | AP17: да | AQ17: да
A18: Seedance 2.0 480p | B18: сек | C18: 5 | D18: 5 | E18: OpenRouter | F18: 0.067 | G18: direct | H18: 0.095 | I18: 20.375 | J18: 128 | K18: =F18*C18*IF(E18="OpenRouter",$F$3,$F$4) -> 35.57097 | L18: =ROUNDUP(5.014*I18,0) -> 103 | M18: =ROUNDUP(K18*(C18/D18)/($B$4*(1-IF(B18="фикс",$B$6,AH18))),0) -> 144 | N18: =ROUNDUP(H18*C18*IF(G18="OpenRouter",$F$3,$F$4)/$B$4,0) -> 145 | O18: =MAX(L18,M18,N18) -> 145 | P18: =ROUND(O18/C18,0) -> 29 | Q18: =1-K18/(O18*$B$4) -> 0.25910938 | T18: 20.375 | U18: публичный прайс Syntx 28.07.2026, цена «итого», пересчёт на длину нашего клипа РЕШЕНИЕ ВЛАДЕЛЬЦА 11.08.2026 — НАДБАВКА ЗА РЕЗЕРВ ОСТАЁТСЯ. Правило цены остаётся из четырёх членов: MAX(потолок +28% vs Syntx; цена по марже 25%; БЕЗУБЫТОК РЕЗЕРВА; ступень качества +15%). Вопрос ставился и закрыт: четвёртый член перебивает цену на 8 строках из 91, и на этих строках клиент оплачивает вторую ногу. Владелец рассмотрел цену решения и принял её. ЧЕГО ЭТО СТОИТ, ЧТОБЫ НИКТО НЕ ПЕРЕСЧИТЫВАЛ ЗАНОВО: на Seedance 1080p 775 вместо 727 — это −7,0% против Syntx вместо −0,9%, то есть страховка стоит 6 п.п. конкурентоспособности. На Gemini Omni 273 вместо 257 — −34,2% вместо −30,1%. На остальных строках надбавка стоит 1-2 кредита и на сравнение с конкурентом не влияет. ЧТО ЭТО ПОКУПАЕТ: переключение на резерв бесплатно для нас в момент отказа — резерв на этих строках выходит ровно в ноль, а не в минус, поэтому R-1 выполняется без исключений и бюджет отказов по R-11 не расходуется. ИЗВЕСТНОЕ ПОБОЧНОЕ СЛЕДСТВИЕ: при этом правиле добавление ЛЮБОЙ новой ноги может цену только поднять, никогда не опустить. Третья нога, под которую 11.08 открыт формат, работает против клиента до тех пор, пока это правило действует. Пересматривать при подключении первого третьего вендора. | V18: =(4400/O18)/(685.5/T18)-1 -> -0.098065847 | W18: =MAX(ROUNDUP(5.014*T18,0),M18,N18) -> 145 | X18: =(4400/W18)/(685.5/T18)-1 -> -0.098065847 | Y18: =1-K18/(W18*$B$4) -> 0.25910938 | AA18: =O18 -> 145 | AB18: =C18 -> 5 | AC18: =IF(B18="шт","—",P18) -> 29 | AD18: OpenRouter | AE18: Kie | AF18: seedance-2-0 | AG18: HIGH | AH18: =$B$5 -> 0.25 | AP18: да | AQ18: да
A19: Seedance Fast 720p | B19: сек | C19: 5 | D19: 5 | E19: OpenRouter | F19: 0.121 | G19: direct | H19: 0.165 | I19: 36.25 | J19: 208 | K19: =F19*C19*IF(E19="OpenRouter",$F$3,$F$4) -> 64.24011 | L19: =ROUNDUP(5.014*I19,0) -> 182 | M19: =ROUNDUP(K19*(C19/D19)/($B$4*(1-IF(B19="фикс",$B$6,AH19))),0) -> 259 | N19: =ROUNDUP(H19*C19*IF(G19="OpenRouter",$F$3,$F$4)/$B$4,0) -> 251 | O19: =MAX(L19,M19,N19) -> 259 | P19: =ROUND(O19/C19,0) -> 52 | Q19: =1-K19/(O19*$B$4) -> 0.25091189 | T19: 36.25 | U19: публичный прайс Syntx 28.07.2026, цена «итого», пересчёт на длину нашего клипа | V19: =(4400/O19)/(685.5/T19)-1 -> -0.10163367 | W19: =MAX(ROUNDUP(5.014*T19,0),M19,N19) -> 259 | X19: =(4400/W19)/(685.5/T19)-1 -> -0.10163367 | Y19: =1-K19/(W19*$B$4) -> 0.25091189 | AA19: =O19 -> 259 | AB19: =C19 -> 5 | AC19: =IF(B19="шт","—",P19) -> 52 | AD19: OpenRouter | AE19: Kie | AF19: seedance-2-0 | AG19: HIGH | AH19: =$B$5 -> 0.25 | AP19: да | AQ19: да
A20: Seedance Fast 480p | B20: сек | C20: 5 | D20: 5 | E20: OpenRouter | F20: 0.0538 | G20: direct | H20: 0.0775 | I20: 16.375 | J20: 98 | K20: =F20*C20*IF(E20="OpenRouter",$F$3,$F$4) -> 28.562958 | L20: =ROUNDUP(5.014*I20,0) -> 83 | M20: =ROUNDUP(K20*(C20/D20)/($B$4*(1-IF(B20="фикс",$B$6,AH20))),0) -> 116 | N20: =ROUNDUP(H20*C20*IF(G20="OpenRouter",$F$3,$F$4)/$B$4,0) -> 118 | O20: =MAX(L20,M20,N20) -> 118 | P20: =ROUND(O20/C20,0) -> 24 | Q20: =1-K20/(O20*$B$4) -> 0.26894919 | T20: 16.375 | U20: публичный прайс Syntx 28.07.2026, цена «итого», пересчёт на длину нашего клипа РЕШЕНИЕ ВЛАДЕЛЬЦА 11.08.2026 — НАДБАВКА ЗА РЕЗЕРВ ОСТАЁТСЯ. Правило цены остаётся из четырёх членов: MAX(потолок +28% vs Syntx; цена по марже 25%; БЕЗУБЫТОК РЕЗЕРВА; ступень качества +15%). Вопрос ставился и закрыт: четвёртый член перебивает цену на 8 строках из 91, и на этих строках клиент оплачивает вторую ногу. Владелец рассмотрел цену решения и принял её. ЧЕГО ЭТО СТОИТ, ЧТОБЫ НИКТО НЕ ПЕРЕСЧИТЫВАЛ ЗАНОВО: на Seedance 1080p 775 вместо 727 — это −7,0% против Syntx вместо −0,9%, то есть страховка стоит 6 п.п. конкурентоспособности. На Gemini Omni 273 вместо 257 — −34,2% вместо −30,1%. На остальных строках надбавка стоит 1-2 кредита и на сравнение с конкурентом не влияет. ЧТО ЭТО ПОКУПАЕТ: переключение на резерв бесплатно для нас в момент отказа — резерв на этих строках выходит ровно в ноль, а не в минус, поэтому R-1 выполняется без исключений и бюджет отказов по R-11 не расходуется. ИЗВЕСТНОЕ ПОБОЧНОЕ СЛЕДСТВИЕ: при этом правиле добавление ЛЮБОЙ новой ноги может цену только поднять, никогда не опустить. Третья нога, под которую 11.08 открыт формат, работает против клиента до тех пор, пока это правило действует. Пересматривать при подключении первого третьего вендора. | V20: =(4400/O20)/(685.5/T20)-1 -> -0.1092732 | W20: =MAX(ROUNDUP(5.014*T20,0),M20,N20) -> 118 | X20: =(4400/W20)/(685.5/T20)-1 -> -0.1092732 | Y20: =1-K20/(W20*$B$4) -> 0.26894919 | AA20: =O20 -> 118 | AB20: =C20 -> 5 | AC20: =IF(B20="шт","—",P20) -> 24 | AD20: OpenRouter | AE20: Kie | AF20: seedance-2-0 | AG20: HIGH | AH20: =$B$5 -> 0.25 | AP20: да | AQ20: да
A21: HappyHorse 1.1 720p | B21: сек | C21: 5 | D21: 5 | E21: OpenRouter | F21: 0.0988 | G21: direct | H21: 0.1125 | I21: 25 | J21: 232 | K21: =F21*C21*IF(E21="OpenRouter",$F$3,$F$4) -> 52.453908 | L21: =ROUNDUP(5.014*I21,0) -> 126 | M21: =ROUNDUP(K21*(C21/D21)/($B$4*(1-IF(B21="фикс",$B$6,AH21))),0) -> 212 | N21: =ROUNDUP(H21*C21*IF(G21="OpenRouter",$F$3,$F$4)/$B$4,0) -> 171 | O21: =MAX(L21,M21,N21) -> 212 | P21: =ROUND(O21/C21,0) -> 42 | Q21: =1-K21/(O21*$B$4) -> 0.25274577 | T21: 25 | U21: публичный прайс Syntx 28.07.2026, цена «итого», пересчёт на длину нашего клипа | V21: =(4400/O21)/(685.5/T21)-1 -> -0.24308107 | W21: =MAX(ROUNDUP(5.014*T21,0),M21,N21) -> 212 | X21: =(4400/W21)/(685.5/T21)-1 -> -0.24308107 | Y21: =1-K21/(W21*$B$4) -> 0.25274577 | AA21: =O21 -> 212 | AB21: =C21 -> 5 | AC21: =IF(B21="шт","—",P21) -> 42 | AD21: OpenRouter | AE21: Kie | AF21: alibaba/happyhorse-1.1 | AG21: HIGH | AH21: =$B$5 -> 0.25 | AP21: да | AQ21: да
A22: HappyHorse 1.1 1080p | B22: сек | C22: 5 | D22: 5 | E22: OpenRouter | F22: 0.1278 | G22: direct | H22: 0.145 | I22: 45 | J22: 301 | K22: =F22*C22*IF(E22="OpenRouter",$F$3,$F$4) -> 67.850298 | L22: =ROUNDUP(5.014*I22,0) -> 226 | M22: =ROUNDUP(K22*(C22/D22)/($B$4*(1-IF(B22="фикс",$B$6,AH22))),0) -> 274 | N22: =ROUNDUP(H22*C22*IF(G22="OpenRouter",$F$3,$F$4)/$B$4,0) -> 221 | O22: =MAX(L22,M22,N22) -> 274 | P22: =ROUND(O22/C22,0) -> 55 | Q22: =1-K22/(O22*$B$4) -> 0.25212746 | T22: 45 | U22: публичный прайс Syntx 28.07.2026, цена «итого», пересчёт на длину нашего клипа | V22: =(4400/O22)/(685.5/T22)-1 -> 0.054161542 | W22: =MAX(ROUNDUP(5.014*T22,0),M22,N22) -> 274 | X22: =(4400/W22)/(685.5/T22)-1 -> 0.054161542 | Y22: =1-K22/(W22*$B$4) -> 0.25212746 | AA22: =O22 -> 274 | AB22: =C22 -> 5 | AC22: =IF(B22="шт","—",P22) -> 55 | AD22: OpenRouter | AE22: Kie | AF22: alibaba/happyhorse-1.1 | AG22: HIGH | AH22: =$B$5 -> 0.25 | AP22: да | AQ22: да
A23: HappyHorse 1.0 720p — СНЯТО | B23: сек | C23: 5 | D23: 5 | E23: OpenRouter | F23: 0.0988 | G23: direct | H23: 0.14 | I23: 25 | J23: 232 | K23: =F23*C23*IF(E23="OpenRouter",$F$3,$F$4) -> 52.453908 | L23: =ROUNDUP(5.014*I23,0) -> 126 | M23: =ROUNDUP(K23*(C23/D23)/($B$4*(1-IF(B23="фикс",$B$6,AH23))),0) -> 212 | N23: 0 | O23: =MAX(L23,M23,N23) -> 212 | P23: =ROUND(O23/C23,0) -> 42 | Q23: =1-K23/(O23*$B$4) -> 0.25274577 | T23: 25 | U23: СНЯТО 03.08.2026. Версия 1.0 дороже 1.1 при том же результате. 1.1 покрывает t2v, i2v и r2v. | V23: =(4400/O23)/(685.5/T23)-1 -> -0.24308107 | W23: =MAX(ROUNDUP(5.014*T23,0),M23,N23) -> 212 | X23: =(4400/W23)/(685.5/T23)-1 -> -0.24308107 | Y23: =1-K23/(W23*$B$4) -> 0.25274577 | AA23: =O23 -> 212 | AB23: =C23 -> 5 | AC23: =IF(B23="шт","—",P23) -> 42 | AD23: OpenRouter | AE23: Kie | AF23: alibaba/happyhorse-1.1 | AG23: HIGH | AH23: =$B$5 -> 0.25
A24: HappyHorse 1.0 1080p — СНЯТО | B24: сек | C24: 5 | D24: 5 | E24: OpenRouter | F24: 0.1694 | G24: direct | H24: 0.24 | I24: 45 | J24: 400 | K24: =F24*C24*IF(E24="OpenRouter",$F$3,$F$4) -> 89.936154 | L24: =ROUNDUP(5.014*I24,0) -> 226 | M24: =ROUNDUP(K24*(C24/D24)/($B$4*(1-IF(B24="фикс",$B$6,AH24))),0) -> 363 | N24: =ROUNDUP(H24*C24*IF(G24="OpenRouter",$F$3,$F$4)/$B$4,0) -> 365 | O24: =MAX(L24,M24,N24) -> 365 | P24: =ROUND(O24/C24,0) -> 73 | Q24: =1-K24/(O24*$B$4) -> 0.2558374 | T24: 45 | U24: СНЯТО С ПРОДАЖИ 03.08.2026 — версия 1.0 дороже 1.1 при том же результате (решение владельца) РЕШЕНИЕ ВЛАДЕЛЬЦА 11.08.2026 — НАДБАВКА ЗА РЕЗЕРВ ОСТАЁТСЯ. Правило цены остаётся из четырёх членов: MAX(потолок +28% vs Syntx; цена по марже 25%; БЕЗУБЫТОК РЕЗЕРВА; ступень качества +15%). Вопрос ставился и закрыт: четвёртый член перебивает цену на 8 строках из 91, и на этих строках клиент оплачивает вторую ногу. Владелец рассмотрел цену решения и принял её. ЧЕГО ЭТО СТОИТ, ЧТОБЫ НИКТО НЕ ПЕРЕСЧИТЫВАЛ ЗАНОВО: на Seedance 1080p 775 вместо 727 — это −7,0% против Syntx вместо −0,9%, то есть страховка стоит 6 п.п. конкурентоспособности. На Gemini Omni 273 вместо 257 — −34,2% вместо −30,1%. На остальных строках надбавка стоит 1-2 кредита и на сравнение с конкурентом не влияет. ЧТО ЭТО ПОКУПАЕТ: переключение на резерв бесплатно для нас в момент отказа — резерв на этих строках выходит ровно в ноль, а не в минус, поэтому R-1 выполняется без исключений и бюджет отказов по R-11 не расходуется. ИЗВЕСТНОЕ ПОБОЧНОЕ СЛЕДСТВИЕ: при этом правиле добавление ЛЮБОЙ новой ноги может цену только поднять, никогда не опустить. Третья нога, под которую 11.08 открыт формат, работает против клиента до тех пор, пока это правило действует. Пересматривать при подключении первого третьего вендора. | V24: =(4400/O24)/(685.5/T24)-1 -> -0.20865681 | W24: =MAX(ROUNDUP(5.014*T24,0),M24,N24) -> 365 | X24: =(4400/W24)/(685.5/T24)-1 -> -0.20865681 | Y24: =1-K24/(W24*$B$4) -> 0.2558374 | AA24: =O24 -> 365 | AB24: =C24 -> 5 | AC24: =IF(B24="шт","—",P24) -> 73 | AD24: OpenRouter | AE24: Kie | AF24: alibaba/happyhorse-1.1 | AG24: HIGH | AH24: =$B$5 -> 0.25
A25: Wan 2.7 720p | B25: сек | C25: 5 | D25: 5 | E25: direct | F25: 0.08 | G25: OpenRouter | H25: 0.1 | I25: 30 | J25: 300 | K25: =F25*C25*IF(E25="OpenRouter",$F$3,$F$4) -> 40.2526 | L25: =ROUNDUP(5.014*I25,0) -> 151 | M25: =ROUNDUP(K25*(C25/D25)/($B$4*(1-IF(B25="фикс",$B$6,AH25))),0) -> 163 | N25: =ROUNDUP(H25*C25*IF(G25="OpenRouter",$F$3,$F$4)/$B$4,0) -> 161 | O25: =MAX(L25,M25,N25) -> 163 | P25: =ROUND(O25/C25,0) -> 33 | Q25: =1-K25/(O25*$B$4) -> 0.25418223 | T25: 30 | U25: публичный прайс Syntx 28.07.2026, цена «итого», пересчёт на длину нашего клипа | V25: =(4400/O25)/(685.5/T25)-1 -> 0.18135077 | W25: =MAX(ROUNDUP(5.014*T25,0),M25,N25) -> 163 | X25: =(4400/W25)/(685.5/T25)-1 -> 0.18135077 | Y25: =1-K25/(W25*$B$4) -> 0.25418223 | AA25: =O25 -> 163 | AB25: =C25 -> 5 | AC25: =IF(B25="шт","—",P25) -> 33 | AD25: Kie | AE25: OpenRouter | AF25: wan-2-7 | AG25: HIGH | AH25: =$B$5 -> 0.25 | AP25: да | AQ25: да
A26: Wan 2.7 1080p | B26: сек | C26: 5 | D26: 5 | E26: direct | F26: 0.12 | G26: OpenRouter | H26: 0.15 | I26: 40 | J26: 300 | K26: =F26*C26*IF(E26="OpenRouter",$F$3,$F$4) -> 60.3789 | L26: =ROUNDUP(5.014*I26,0) -> 201 | M26: =ROUNDUP(K26*(C26/D26)/($B$4*(1-IF(B26="фикс",$B$6,AH26))),0) -> 244 | N26: =ROUNDUP(H26*C26*IF(G26="OpenRouter",$F$3,$F$4)/$B$4,0) -> 241 | O26: =MAX(L26,M26,N26) -> 244 | P26: =ROUND(O26/C26,0) -> 49 | Q26: =1-K26/(O26*$B$4) -> 0.25265392 | T26: 40 | U26: публичный прайс Syntx 28.07.2026, цена «итого», пересчёт на длину нашего клипа | V26: =(4400/O26)/(685.5/T26)-1 -> 0.052241394 | W26: =MAX(ROUNDUP(5.014*T26,0),M26,N26) -> 244 | X26: =(4400/W26)/(685.5/T26)-1 -> 0.052241394 | Y26: =1-K26/(W26*$B$4) -> 0.25265392 | AA26: =O26 -> 244 | AB26: =C26 -> 5 | AC26: =IF(B26="шт","—",P26) -> 49 | AD26: Kie | AE26: OpenRouter | AF26: wan-2-7 | AG26: HIGH | AH26: =$B$5 -> 0.25 | AP26: да | AQ26: да
A27: Kling v3 720p (звук) | B27: сек | C27: 5 | D27: 5 | E27: OpenRouter | F27: 0.126 | G27: — | H27: — | I27: 25 | J27: 350 | K27: =F27*C27*IF(E27="OpenRouter",$F$3,$F$4) -> 66.89466 | L27: =ROUNDUP(5.014*I27,0) -> 126 | M27: =ROUNDUP(K27*(C27/D27)/($B$4*(1-IF(B27="фикс",$B$6,AH27))),0) -> 270 | N27: 0 | O27: =MAX(L27,M27,N27) -> 270 | P27: =ROUND(O27/C27,0) -> 54 | Q27: =1-K27/(O27*$B$4) -> 0.25173733 | U27: ЕДИНСТВЕННАЯ НОГА — OpenRouter. Ноги kie у этой модели не существует: ни слага в адаптере, ни переопределения шлюза, ни в контракте маршрута. Ставка kie, по которой строка была оценена в ред.10, относилась к маршруту, которого нет. Пересчитано от реальной ноги 04.08.2026. Standard $0,126/с со звуком, $0,084/с без звука (Pro $0,168/$0,112 не продаём). | AA27: =O27 -> 270 | AB27: =C27 -> 5 | AC27: =IF(B27="шт","—",P27) -> 54 | AD27: OpenRouter | AE27: — | AF27: kwaivgi/kling-v3.0-std | AG27: HIGH — прайс OpenRouter, Standard | AH27: =$B$5 -> 0.25 | AP27: да
A28: Grok 720p | B28: сек | C28: 6 | D28: 6 | E28: direct | F28: 0.0225 | G28: — | H28: — | I28: 8 | J28: 45 | K28: =F28*C28*IF(E28="OpenRouter",$F$3,$F$4) -> 13.585252 | L28: =ROUNDUP(5.014*I28,0) -> 41 | M28: =ROUNDUP(K28*(C28/D28)/($B$4*(1-IF(B28="фикс",$B$6,AH28))),0) -> 69 | N28: 0 | O28: =MAX(L28,M28,N28) -> 69 | P28: =ROUND(O28/C28,0) -> 12 | Q28: =1-K28/(O28*$B$4) -> 0.40537247 | T28: 8 | U28: Ставка подтверждена прайсом kie. Порог 40% по R-10 остаётся: xAI просит $0,05/$0,07, kie на 68-76% ниже, второй ноги нет, и kie уже двигал ставку на +50% за две недели. Оба условия правила в силе. | V28: =(4400/O28)/(685.5/T28)-1 -> -0.25580609 | W28: =MAX(ROUNDUP(5.014*T28,0),M28,N28) -> 69 | X28: =(4400/W28)/(685.5/T28)-1 -> -0.25580609 | Y28: =1-K28/(W28*$B$4) -> 0.40537247 | AA28: =O28 -> 69 | AB28: =C28 -> 6 | AC28: =IF(B28="шт","—",P28) -> 12 | AD28: Kie | AE28: — | AF28: grok-imagine-video | AG28: HIGH — прайс kie 04.08.2026. Порог 40% сохраняется по R-10: подтверждение источника снимает сомнение в чтении ставки, но не в её устойчивости. | AH28: 0.4 | AP28: да
A29: Grok 480p | B29: сек | C29: 6 | D29: 6 | E29: direct | F29: 0.012 | G29: — | H29: — | I29: 5 | J29: 24 | K29: =F29*C29*IF(E29="OpenRouter",$F$3,$F$4) -> 7.245468 | L29: =ROUNDUP(5.014*I29,0) -> 26 | M29: =ROUNDUP(K29*(C29/D29)/($B$4*(1-IF(B29="фикс",$B$6,AH29))),0) -> 37 | N29: 0 | O29: =MAX(L29,M29,N29) -> 37 | P29: =ROUND(O29/C29,0) -> 6 | Q29: =1-K29/(O29*$B$4) -> 0.40858667 | T29: 5 | U29: Ставка подтверждена прайсом kie. Порог 40% по R-10 остаётся: xAI просит $0,05/$0,07, kie на 68-76% ниже, второй ноги нет, и kie уже двигал ставку на +50% за две недели. Оба условия правила в силе. | V29: =(4400/O29)/(685.5/T29)-1 -> -0.13261182 | W29: =MAX(ROUNDUP(5.014*T29,0),M29,N29) -> 37 | X29: =(4400/W29)/(685.5/T29)-1 -> -0.13261182 | Y29: =1-K29/(W29*$B$4) -> 0.40858667 | AA29: =O29 -> 37 | AB29: =C29 -> 6 | AC29: =IF(B29="шт","—",P29) -> 6 | AD29: Kie | AE29: — | AF29: grok-imagine-video | AG29: HIGH — прайс kie 04.08.2026. Порог 40% сохраняется по R-10: подтверждение источника снимает сомнение в чтении ставки, но не в её устойчивости. | AH29: 0.4 | AP29: да
A30: Gemini Omni | B30: сек | C30: 8 | D30: 8 | E30: direct | F30: 0.079 | G30: direct | H30: 0.112 | I30: 28 | J30: 282 | K30: =F30*C30*IF(E30="OpenRouter",$F$3,$F$4) -> 63.599108 | L30: =ROUNDUP(5.014*I30,0) -> 141 | M30: =ROUNDUP(K30*(C30/D30)/($B$4*(1-IF(B30="фикс",$B$6,AH30))),0) -> 257 | N30: =ROUNDUP(H30*C30*IF(G30="OpenRouter",$F$3,$F$4)/$B$4,0) -> 273 | O30: =MAX(L30,M30,N30) -> 273 | P30: =ROUND(O30/C30,0) -> 34 | Q30: =1-K30/(O30*$B$4) -> 0.29641792 | U30: ДВЕ НОГИ ВОССТАНОВЛЕНЫ 04.08.2026. Решение от 03.08 снять AtlasCloud принималось при ставке $0,125-0,135, которая требовала 329 кредитов — плюс 21% клиенту за страховку. При подтверждённых $0,112 требуется 273, то есть плюс 6%. Модель несёт 8% потребления и не имеет альтернативного источника дешевле $0,084/с — за две ноги на такой строке 6% платить стоит. РЕШЕНИЕ ВЛАДЕЛЬЦА 11.08.2026 — НАДБАВКА ЗА РЕЗЕРВ ОСТАЁТСЯ. Правило цены остаётся из четырёх членов: MAX(потолок +28% vs Syntx; цена по марже 25%; БЕЗУБЫТОК РЕЗЕРВА; ступень качества +15%). Вопрос ставился и закрыт: четвёртый член перебивает цену на 8 строках из 91, и на этих строках клиент оплачивает вторую ногу. Владелец рассмотрел цену решения и принял её. ЧЕГО ЭТО СТОИТ, ЧТОБЫ НИКТО НЕ ПЕРЕСЧИТЫВАЛ ЗАНОВО: на Seedance 1080p 775 вместо 727 — это −7,0% против Syntx вместо −0,9%, то есть страховка стоит 6 п.п. конкурентоспособности. На Gemini Omni 273 вместо 257 — −34,2% вместо −30,1%. На остальных строках надбавка стоит 1-2 кредита и на сравнение с конкурентом не влияет. ЧТО ЭТО ПОКУПАЕТ: переключение на резерв бесплатно для нас в момент отказа — резерв на этих строках выходит ровно в ноль, а не в минус, поэтому R-1 выполняется без исключений и бюджет отказов по R-11 не расходуется. ИЗВЕСТНОЕ ПОБОЧНОЕ СЛЕДСТВИЕ: при этом правиле добавление ЛЮБОЙ новой ноги может цену только поднять, никогда не опустить. Третья нога, под которую 11.08 открыт формат, работает против клиента до тех пор, пока это правило действует. Пересматривать при подключении первого третьего вендора. | AA30: =O30 -> 273 | AB30: =C30 -> 8 | AC30: =IF(B30="шт","—",P30) -> 34 | AD30: Kie | AE30: AtlasCloud | AF30: gemini-omni-flash | AG30: HIGH — ставка подтверждена платно | AH30: =$B$5 -> 0.25 | AI30: ТАРИФ МАРШРУТА AtlasCloud: $0,112/с держится только на ступени -developer. Стандартная ступень $0,125-0,135, и при 273 кредитах это −11,3% вместо +0,25%. Риск управляется нами, а не поставщиком: суффикс закреплён именованной константой с тестом на три режима. Внешнего сигнала у потери суффикса нет — Atlas отвечает, отдаёт видео и просто выставляет счёт дороже. | AP30: да | AQ30: да
A31: nano-banana | B31: карт | C31: 1 | D31: 1 | E31: direct | F31: 0.02 | G31: direct | H31: 0.02 | I31: 1.5 | J31: 15 | K31: =F31*C31*IF(E31="OpenRouter",$F$3,$F$4) -> 2.01263 | L31: =ROUNDUP(5.014*I31,0) -> 8 | M31: =ROUNDUP(K31*(C31/D31)/($B$4*(1-IF(B31="фикс",$B$6,AH31))),0) -> 9 | N31: 0 | O31: =MAX(L31,M31,N31) -> 9 | P31: =ROUND(O31/C31,0) -> 9 | Q31: =1-K31/(O31*$B$4) -> 0.32462058 | U31: Kie fallback google/nano-banana $0.02/img; owner list 2026-07-25; t2i route connected. | AA31: =O31 -> 9 | AB31: =C31 -> 1 | AC31: =IF(B31="шт","—",P31) -> 9 | AD31: LaoZhang | AE31: Kie | AF31: gemini-2-5-flash-image | AG31: HIGH; ЕДИНСТВЕННАЯ НОГА — резерва не существует | AH31: =$B$5 -> 0.25 | AP31: да | AQ31: да
A32: nano-banana-2 1K | B32: карт | C32: 1 | D32: 1 | E32: direct | F32: 0.04 | G32: direct | H32: 0.055 | I32: 3 | J32: 25 | K32: =F32*C32*IF(E32="OpenRouter",$F$3,$F$4) -> 4.02526 | L32: =ROUNDUP(5.014*I32,0) -> 16 | M32: =ROUNDUP(K32*(C32/D32)/($B$4*(1-IF(B32="фикс",$B$6,AH32))),0) -> 17 | N32: =ROUNDUP(H32*C32*IF(G32="OpenRouter",$F$3,$F$4)/$B$4,0) -> 17 | O32: =MAX(L32,M32,N32) -> 17 | P32: =ROUND(O32/C32,0) -> 17 | Q32: =1-K32/(O32*$B$4) -> 0.28489238 | U32: Ноги поменяны местами 03.08: kie по опубликованной лестнице дешевле LaoZhang на этом рунге. | Z32: 0 | AA32: =O32 -> 17 | AB32: =C32 -> 1 | AC32: =IF(B32="шт","—",P32) -> 17 | AD32: Kie | AE32: LaoZhang | AF32: nano-banana-2 | AG32: HIGH | AH32: =$B$5 -> 0.25 | AP32: да | AQ32: да
A33: nano-banana-2-lite | B33: карт | C33: 1 | D33: 1 | E33: direct | F33: 0.02 | G33: direct | H33: 0.025 | I33: 1.3 | J33: 12 | K33: =F33*C33*IF(E33="OpenRouter",$F$3,$F$4) -> 2.01263 | L33: =ROUNDUP(5.014*I33,0) -> 7 | M33: =ROUNDUP(K33*(C33/D33)/($B$4*(1-IF(B33="фикс",$B$6,AH33))),0) -> 9 | N33: =ROUNDUP(H33*C33*IF(G33="OpenRouter",$F$3,$F$4)/$B$4,0) -> 8 | O33: =MAX(L33,M33,N33) -> 9 | P33: =ROUND(O33/C33,0) -> 9 | Q33: =1-K33/(O33*$B$4) -> 0.32462058 | U33: Ноги поменяны местами 03.08: kie по опубликованной лестнице дешевле LaoZhang на этом рунге. | AA33: =O33 -> 9 | AB33: =C33 -> 1 | AC33: =IF(B33="шт","—",P33) -> 9 | AD33: Kie | AE33: LaoZhang | AF33: nano-banana-2-lite | AG33: HIGH | AH33: =$B$5 -> 0.25 | AP33: да | AQ33: да
A34: nano-banana-pro 1K | B34: карт | C34: 1 | D34: 1 | E34: direct | F34: 0.09 | G34: — | H34: — | I34: 2 | J34: 40 | K34: =F34*C34*IF(E34="OpenRouter",$F$3,$F$4) -> 9.056835 | L34: =ROUNDUP(5.014*I34,0) -> 11 | M34: =ROUNDUP(K34*(C34/D34)/($B$4*(1-IF(B34="фикс",$B$6,AH34))),0) -> 37 | N34: 0 | O34: =MAX(L34,M34,N34) -> 37 | P34: =ROUND(O34/C34,0) -> 37 | Q34: =1-K34/(O34*$B$4) -> 0.26073334 | U34: ВТОРОЙ НОГИ НЕТ. В колонках резерва стояла побайтовая копия основной ставки без имени поставщика — заглушка, которую экспорт выгружал как настоящую ногу. Убрана 10.08.2026. Модель обслуживается одним LaoZhang: при его недоступности строка не переключается, а отказывает. Это факт для бюджета отказов, а не дефект цены — цена и маржа не менялись. | Z34: 0 | AA34: =O34 -> 37 | AB34: =C34 -> 1 | AC34: =IF(B34="шт","—",P34) -> 37 | AD34: LaoZhang | AE34: — | AF34: nano-banana-pro | AG34: HIGH; ЕДИНСТВЕННАЯ НОГА — резерва не существует | AH34: =$B$5 -> 0.25 | AP34: да
A35: nano-banana-pro 4K | B35: карт | C35: 1 | D35: 1 | E35: direct | F35: 0.09 | G35: direct | H35: 0.12 | I35: 2 | J35: 41 | K35: =F35*C35*IF(E35="OpenRouter",$F$3,$F$4) -> 9.056835 | L35: =ROUNDUP(5.014*I35,0) -> 11 | M35: =ROUNDUP(K35*(C35/D35)/($B$4*(1-IF(B35="фикс",$B$6,AH35))),0) -> 37 | N35: =ROUNDUP(H35*C35*IF(G35="OpenRouter",$F$3,$F$4)/$B$4,0) -> 37 | O35: =MAX(L35,M35,N35,Z35) -> 50 | P35: =ROUND(O35/C35,0) -> 50 | Q35: =1-K35/(O35*$B$4) -> 0.45294267 | U35: НЕ ПРОВЕРЕНО — публичным прайсом не подтверждено | Z35: =ROUNDUP(O46*1.15,0) -> 50 | AA35: =O35 -> 50 | AB35: =C35 -> 1 | AC35: =IF(B35="шт","—",P35) -> 50 | AD35: LaoZhang | AE35: Kie | AF35: nano-banana-pro | AG35: HIGH | AH35: =$B$5 -> 0.25 | AP35: да | AQ35: да
A36: gpt-image-2 1K (low) | B36: карт | C36: 1 | D36: 1 | E36: direct | F36: 0.03 | G36: direct | H36: 0.03 | I36: 2 | J36: 25 | K36: =F36*C36*IF(E36="OpenRouter",$F$3,$F$4) -> 3.018945 | L36: =ROUNDUP(5.014*I36,0) -> 11 | M36: =ROUNDUP(K36*(C36/D36)/($B$4*(1-IF(B36="фикс",$B$6,AH36))),0) -> 13 | N36: 0 | O36: =MAX(L36,M36,N36) -> 13 | P36: =ROUND(O36/C36,0) -> 13 | Q36: =1-K36/(O36*$B$4) -> 0.29864445 | U36: Kie fallback gpt-image-2-text-to-image $0.03/low; owner list 2026-07-25. Costed reserve; quality mapping remains unarmed. | AA36: =O36 -> 13 | AB36: =C36 -> 1 | AC36: =IF(B36="шт","—",P36) -> 13 | AD36: LaoZhang | AE36: Kie | AF36: gpt-image-2-vip | AG36: ЗАМЕРЕНО 09.08.2026 — платный вызов, счётчик откалиброван | AH36: =$B$5 -> 0.25 | AP36: да
A37: gpt-image-2 2K (medium) | B37: шт | C37: 1 | D37: 1 | E37: direct | F37: 0.03 | G37: direct | H37: 0.05 | I37: — | K37: =F37*C37*IF(E37="OpenRouter",$F$3,$F$4) -> 3.018945 | L37: 0 | M37: =ROUNDUP(K37*(C37/D37)/($B$4*(1-IF(B37="фикс",$B$6,AH37))),0) -> 13 | N37: 0 | O37: 21 | P37: =ROUND(O37/C37,0) -> 21 | Q37: =1-K37/(O37*$B$4) -> 0.56582751 | U37: Kie fallback gpt-image-2-text-to-image $0.05/medium; owner list 2026-07-25. Costed reserve; quality mapping remains unarmed. | AA37: =O37 -> 21 | AB37: =C37 -> 1 | AC37: =IF(B37="шт","—",P37) -> — | AD37: LaoZhang | AE37: Kie | AF37: gpt-image-2-vip | AG37: ЗАМЕРЕНО 09.08.2026 — платный вызов, счётчик откалиброван | AH37: =$B$5 -> 0.25 | AP37: да
A38: gpt-image-2 4K (high) | B38: шт | C38: 1 | D38: 1 | E38: direct | F38: 0.03 | G38: direct | H38: 0.08 | I38: — | K38: =F38*C38*IF(E38="OpenRouter",$F$3,$F$4) -> 3.018945 | L38: 0 | M38: =ROUNDUP(K38*(C38/D38)/($B$4*(1-IF(B38="фикс",$B$6,AH38))),0) -> 13 | N38: 0 | O38: 33 | P38: =ROUND(O38/C38,0) -> 33 | Q38: =1-K38/(O38*$B$4) -> 0.72370842 | U38: Kie fallback gpt-image-2-text-to-image $0.08/high; owner list 2026-07-25. Costed reserve; quality mapping remains unarmed. | AA38: =O38 -> 33 | AB38: =C38 -> 1 | AC38: =IF(B38="шт","—",P38) -> — | AD38: LaoZhang | AE38: Kie | AF38: gpt-image-2-vip | AG38: ЗАМЕРЕНО 09.08.2026 — платный вызов, счётчик откалиброван | AH38: =$B$5 -> 0.25 | AP38: да
A39: seedream-4.5 1K | B39: карт | C39: 1 | D39: 1 | E39: direct | F39: 0.0325 | G39: OpenRouter | H39: 0.04 | I39: 2 | J39: 15 | K39: =F39*C39*IF(E39="OpenRouter",$F$3,$F$4) -> 3.2705238 | L39: =ROUNDUP(5.014*I39,0) -> 11 | M39: =ROUNDUP(K39*(C39/D39)/($B$4*(1-IF(B39="фикс",$B$6,AH39))),0) -> 14 | N39: =ROUNDUP(H39*C39*IF(G39="OpenRouter",$F$3,$F$4)/$B$4,0) -> 13 | O39: =MAX(L39,M39,N39) -> 14 | P39: =ROUND(O39/C39,0) -> 14 | Q39: =1-K39/(O39*$B$4) -> 0.29446971 | U39: НЕ ПРОВЕРЕНО — публичным прайсом не подтверждено | Z39: 0 | AA39: =O39 -> 14 | AB39: =C39 -> 1 | AC39: =IF(B39="шт","—",P39) -> 14 | AD39: Kie | AE39: OpenRouter | AF39: seedream-4-5 | AG39: HIGH | AH39: =$B$5 -> 0.25 | AP39: да | AQ39: да
A40: seedream-5.0 Pro 1K · 0-1 реф | B40: карт | C40: 1 | D40: 1 | E40: direct | F40: 0.035 | G40: — | H40: — | I40: 3 | J40: 15 | K40: =F40*C40*IF(E40="OpenRouter",$F$3,$F$4) -> 3.5221025 | L40: =ROUNDUP(5.014*I40,0) -> 16 | M40: =ROUNDUP(K40*(C40/D40)/($B$4*(1-IF(B40="фикс",$B$6,AH40))),0) -> 15 | N40: 0 | O40: =MAX(L40,M40,N40) -> 16 | P40: =ROUND(O40/C40,0) -> 16 | Q40: =1-K40/(O40*$B$4) -> 0.33517338 | T40: 3 | U40: Диапазон 0-1 референс. kie берёт за входные картинки $0,0025 начиная СО ВТОРОЙ — первая бесплатна, и SKU image-to-image стоит столько же, сколько text-to-image. Значит один референс не меняет себестоимость и цену. Разрыв в бандах устранён 04.08.2026 переименованием, без изменения цены. | V40: =(4400/O40)/(685.5/T40)-1 -> 0.20350109 | W40: =MAX(ROUNDUP(5.014*T40,0),M40,N40) -> 16 | X40: =(4400/W40)/(685.5/T40)-1 -> 0.20350109 | Y40: =1-K40/(W40*$B$4) -> 0.33517338 | AA40: =O40 -> 16 | AB40: =C40 -> 1 | AC40: =IF(B40="шт","—",P40) -> 16 | AD40: Kie | AE40: — | AF40: seedream/5-pro-text-to-image | AG40: HIGH | AH40: =$B$5 -> 0.25 | AP40: да
...

Sheet НОГИ (экспорт)
A1: ЭКСПОРТ ДЛЯ ДВИЖКА МАРШРУТИЗАЦИИ · ВЕРСИЯ 2026-08-14 · РЕД. 22 · ЛИСТ ГЕНЕРИРУЕТСЯ ЦЕЛИКОМ ИЗ «Сетка FX», НИКОГДА НЕ ПРАВИТСЯ ТОЧЕЧНО
A2: КЛЮЧ КОНФИГУРАЦИИ — A+B+C+D+E+Y (model_id | rung | mode | audio | quality | aspect); КЛЮЧ СТРОКИ добавляет ногу
A3: СТРОК ДАННЫХ: 140 · КОНТРОЛЬНАЯ СУММА КРЕДИТОВ: 26729 · КОНТРОЛЬНАЯ СУММА МАРЖИ: 35.241635 · РАЗЛИЧНЫХ КЛЮЧЕЙ СТРОК: 140
A4: РЕД. 22: добавлены восемь подписанных fallback-cost rows: gemini-2.5 flash image для t2i/i2i и GPT Image 2 для low/medium/high в t2i/i2i. GPT quality rows costed for margin governance; route remains unarmed until Kie quality mapping is approved. Workbook remains the SSOT; regenerate cost-legs.csv after every financial edit.
A5: ОТПЕЧАТОК ПОРЯДКА КОЛОНОК: da54ec1b730a358b · КОЛОНОК: 34 — четвёртая контрольная сумма, добавлена 11.08.2026. Три прежние суммы складывают числа и поэтому НЕ МЕНЯЮТСЯ при боковом сдвиге колонок. Этот отпечаток — хэш имён колонок в их порядке; он ломается от сдвига, вставки и переименования. Если он не совпал, а суммы совпали — читайте структуру, а не цифры.
A7: model_id | B7: rung | C7: mode | D7: audio | E7: quality | F7: leg | G7: Роль | H7: ПОСРЕДНИК | I7: АПСТРЕМ | J7: SKU у поставщика | K7: Канал | L7: Множ. | M7: База тарификации | N7: $ за ед. | O7: Landed ₽/ед | P7: Себест ₽ | Q7: Себест известна | R7: ДОСТОВЕРНОСТЬ | S7: Кредитов | T7: Маржа ноги | U7: ГЛУБИНА ЛЕСТНИЦЫ | V7: Источник | W7: Дата ISO | X7: Количество | Y7: aspect | Z7: refs_min | AA7: refs_max | AB7: цена_в_полосе | AC7: доплата_$_за_картинку | AD7: КЛЮЧ конфигурации | AE7: КЛЮЧ строки | AF7: РИСК МАРШРУТА | AG7: ступень_по_умолчанию | AH7: площадь_МП
A8: veo-3-1 | B8: 720p | C8: t2v | D8: да | F8: 1 | G8: основная | H8: Kie | I8: Google | J8: veo-3-1 | K8: прямой | L8: 1.1839 | M8: за клип | N8: 1.25 | O8: 100.6315 | P8: 125.79 | Q8: да | R8: HIGH — бенчмарк Syntx подтверждён владельцем 03.08.2026 | S8: 597 | T8: 0.36365 | U8: 1 | V8: Сетка FX стр.9 | W8: 2026-08-11 | X8: 1 | Y8: any | Z8: 0 | AA8: 0 | AB8: плоская | AC8: 0 | AD8: veo-3-1|720p|t2v|да|-|any | AE8: veo-3-1|720p|t2v|да|-|any|нога1 | AG8: 1080p
A9: veo-3-1 | B9: 1080p | C9: t2v | D9: да | F9: 1 | G9: основная | H9: Kie | I9: Google | J9: veo-3-1 | K9: прямой | L9: 1.1839 | M9: за клип | N9: 1.275 | O9: 100.6315 | P9: 128.31 | Q9: да | R9: HIGH — бенчмарк Syntx подтверждён владельцем 03.08.2026 | S9: 597 | T9: 0.350923 | U9: 1 | V9: Сетка FX стр.10 | W9: 2026-08-11 | X9: 1 | Y9: any | Z9: 0 | AA9: 0 | AB9: плоская | AC9: 0 | AD9: veo-3-1|1080p|t2v|да|-|any | AE9: veo-3-1|1080p|t2v|да|-|any|нога1 | AG9: 1080p
A10: veo-3-1-fast | B10: 720p | C10: t2v | D10: да | F10: 1 | G10: основная | H10: Kie | I10: Google | J10: veo-3-1 | K10: прямой | L10: 1.1839 | M10: за клип | N10: 0.3 | O10: 100.6315 | P10: 30.19 | Q10: да | R10: HIGH — бенчмарк Syntx подтверждён владельцем 03.08.2026 | S10: 122 | T10: 0.252654 | U10: 1 | V10: Сетка FX стр.11 | W10: 2026-08-11 | X10: 1 | Y10: any | Z10: 0 | AA10: 0 | AB10: плоская | AC10: 0 | AD10: veo-3-1-fast|720p|t2v|да|-|any | AE10: veo-3-1-fast|720p|t2v|да|-|any|нога1 | AG10: 720p
A11: veo-3-1-fast | B11: 1080p | C11: t2v | D11: да | F11: 1 | G11: основная | H11: Kie | I11: Google | J11: veo-3-1 | K11: прямой | L11: 1.1839 | M11: за клип | N11: 0.325 | O11: 100.6315 | P11: 32.71 | Q11: да | R11: HIGH — бенчмарк Syntx подтверждён владельцем 03.08.2026 | S11: 132 | T11: 0.25171 | U11: 1 | V11: Сетка FX стр.12 | W11: 2026-08-11 | X11: 1 | Y11: any | Z11: 0 | AA11: 0 | AB11: плоская | AC11: 0 | AD11: veo-3-1-fast|1080p|t2v|да|-|any | AE11: veo-3-1-fast|1080p|t2v|да|-|any|нога1 | AG11: 720p
A12: veo-3-1-lite | B12: 720p | C12: t2v | D12: да | F12: 1 | G12: основная | H12: Kie | I12: Google | J12: veo-3-1 | K12: прямой | L12: 1.1839 | M12: за клип | N12: 0.15 | O12: 100.6315 | P12: 15.09 | Q12: да | R12: HIGH — бенчмарк Syntx подтверждён владельцем 03.08.2026 | S12: 66 | T12: 0.309271 | U12: 1 | V12: Сетка FX стр.13 | W12: 2026-08-11 | X12: 1 | Y12: any | Z12: 0 | AA12: 0 | AB12: плоская | AC12: 0 | AD12: veo-3-1-lite|720p|t2v|да|-|any | AE12: veo-3-1-lite|720p|t2v|да|-|any|нога1 | AG12: 720p
A13: veo-3-1-lite | B13: 1080p | C13: t2v | D13: да | F13: 1 | G13: основная | H13: Kie | I13: Google | J13: veo-3-1 | K13: прямой | L13: 1.1839 | M13: за клип | N13: 0.175 | O13: 100.6315 | P13: 17.61 | Q13: да | R13: HIGH — бенчмарк Syntx подтверждён владельцем 03.08.2026 | S13: 71 | T13: 0.2509 | U13: 1 | V13: Сетка FX стр.14 | W13: 2026-08-11 | X13: 1 | Y13: any | Z13: 0 | AA13: 0 | AB13: плоская | AC13: 0 | AD13: veo-3-1-lite|1080p|t2v|да|-|any | AE13: veo-3-1-lite|1080p|t2v|да|-|any|нога1 | AG13: 720p
A14: seedance-2-0 | B14: 4K | C14: t2v | D14: нет | F14: 1 | G14: основная | H14: Kie | I14: ByteDance | J14: seedance-2-0 | K14: прямой | L14: 1.1839 | M14: за секунду | N14: 1.04 | O14: 100.6315 | P14: 523.28 | Q14: да | R14: HIGH — ставки платно подтверждены; имена посредников исправлены 10.08.2026 (были переставлены) | S14: 2108 | T14: 0.25029 | U14: 1 | V14: Сетка FX стр.15 | W14: 2026-08-11 | X14: 5 | Y14: any | Z14: 0 | AA14: 0 | AB14: плоская | AC14: 0 | AD14: seedance-2-0|4K|t2v|нет|-|any | AE14: seedance-2-0|4K|t2v|нет|-|any|нога1 | AG14: 480p
A15: seedance-2-0 | B15: 1080p | C15: t2v | D15: нет | F15: 1 | G15: основная | H15: OpenRouter | I15: ByteDance | J15: seedance-2-0 | K15: OpenRouter | L15: 1.2492 | M15: за секунду | N15: 0.34 | O15: 106.182 | P15: 180.51 | Q15: да | R15: HIGH | S15: 775 | T15: 0.296564 | U15: 2 | V15: Сетка FX стр.16 | W15: 2026-08-11 | X15: 5 | Y15: any | Z15: 0 | AA15: 0 | AB15: плоская | AC15: 0 | AD15: seedance-2-0|1080p|t2v|нет|-|any | AE15: seedance-2-0|1080p|t2v|нет|-|any|нога1 | AG15: 480p
A16: seedance-2-0 | B16: 1080p | C16: t2v | D16: нет | F16: 2 | G16: резервная | H16: Kie | I16: ByteDance | J16: seedance-2-0 | K16: прямой | L16: 1.1839 | M16: за секунду | N16: 0.51 | O16: 100.6315 | P16: 256.61 | Q16: да | R16: HIGH | S16: 775 | T16: 3e-06 | U16: 2 | V16: Сетка FX стр.16 | W16: 2026-08-11 | X16: 5 | Y16: any | Z16: 0 | AA16: 0 | AB16: плоская | AC16: 0 | AD16: seedance-2-0|1080p|t2v|нет|-|any | AE16: seedance-2-0|1080p|t2v|нет|-|any|нога2 | AG16: 480p
